Workbook

Sheet CABD 2025-2
F1: Semana 1: | G1: 45867 | H1: Semana 2: | I1: 45874 | J1: Semana 3: | K1: 45881 | L1: Semana 4: | M1: 45888 | N1: Semana 5: | O1: 45895 | P1: Semana 6: | Q1: 45902 | AA1: Promedio tareas: 70% | AB1: Semana 7: | AC1: 45909 | AD1: Semana 8: | AE1: 45916 | AF1: Semana 9: | AG1: 45923 | AH1: Semana 10: | AI1: 45930 | AJ1: Semana 11: | AK1: 45930 | AL1: Semana 12: | AM1: 45944 | AU1: Semana 13: | AV1: 45951 | AW1: Semana 14: | AX1: 45958 | AY1: Semana 15: | AZ1: 45965 | BA1: Semana 16: | BB1: 45972
F2: T.Encuentro: | G2: 0.01744213 | H2: T.Encuentro | I2: 0.039780093 | J2: T.Encuentro | K2: 0.035949074 | L2: T.Encuentro | M2: 0.022731481 | N2: T.Encuentro | O2: 0.046655093 | P2: T.Encuentro | Q2: 0.043206019 | AA2: Asistencia: 30% | AB2: T.Encuentro | AC2: 0.041157407 | AD2: T.Encuentro | AE2: 0.037534722 | AF2: T.Encuentro | AG2: 0.037534722 | AH2: T.Encuentro | AI2: 0.014722222 | AJ2: T.Encuentro | AK2: 0.035925926 | AL2: T.Encuentro | AM2: 0.029988426 | AU2: T.Encuentro | AV2: 0.03712963 | AW2: T.Encuentro | AX2: 0.032650463 | AY2: T.Encuentro | AZ2: 0.036354167 | BA2: T.Encuentro | BB2: 0.0340625
A3: Num | B3: Apellidos | C3: Nombres | D3: id | E3: email | F3: T.Conexión | G3: %Conexión | H3: T.Conexión2 | I3: %Conexión2 | J3: T.Conexión3 | K3: %Conexión3 | L3: T.Conexión4 | M3: %Conexión4 | N3: T.Conexión5 | O3: %Conexión5 | P3: T.Conexión6 | Q3: %Conexión6 | R3: Asistencia | S3: Grupo | T3: Gesto Asignado | U3: Conceptos fundamentales (Semana 1) | V3: Operaciones sobre piezas (Semana 2) | W3: Operaciones básicas para Modelado de Superficies (Semana 3) | X3: Modelado avanzado y reparación de Superficies (Semana 4) | Y3: Modelado a partir de datos de scanner (Semana 5) | Z3: Escaneo de partes anatómicas (Semana 6) | AA3: Nota 1er Corte | AB3: T.Conexión7 | AC3: %Conexión7 | AD3: T.Conexión8 | AE3: %Conexión8 | AF3: T.Conexión9 | AG3: %Conexión9 | AH3: T.Conexión10 | AI3: %Conexión10 | AJ3: T.Conexión11 | AK3: %Conexión11 | AL3: T.Conexión12 | AM3: %Conexión12 | AN3: Asistencia 2o Corte | AO3: Tarea:Introducción a 3DSlicer (Semana 8) (Real) | AP3: Tarea:Segmentación Manual y Semi-Automática (Semana 10) (Real) | AQ3: Nota 2o Corte | AR3: DICOM craneal | AS3: Uso de métricas | AT3: Uso de scripts | AU3: T.Conexión13 | AV3: %Conexión13 | AW3: T.Conexión14 | AX3: %Conexión14 | AY3: T.Conexión15 | AZ3: %Conexión15 | BA3: T.Conexión16 | BB3: %Conexión16 | BC3: Guía 1 | BD3: Guía 2 | BE3: Guía 3 | BF3: Final | BG3: Column1 | BH3: nota asistencia | BI3: Tarea:Impresión 3D (Semana 13) (Real) | BJ3: Tarea:Posicionamiento de Tornillo Para Osteosíntesis (Semana 14) (Real) | BK3: Tarea:Diseño de Guía Quirúrgica Maxilofacial (Semana 15) (Real) | BL3: Tarea:Guía para Resección Tumoral (Semana 16) (Real) | BM3: Tarea:Evaluación Final Sincrónica (Semana 17) (Real) | BN3: Nota 3er corte | BO3: Def
A4: 1 | B4: BERMUDEZ DIAZ | C4: JUAN ESTEBAN | D4: 1005785665 | E4: juan_est.bermudez@uao.edu.co | F4: 0 | G4: =IF(F4/$G$2<=1.001,F4/$G$2,0.6) -> 0 | H4: 0.039085648 | I4: =IF(H4/$I$2<=1.001,H4/$I$2,0.6) -> 0.98254292 | J4: 0.035960648 | K4: =IF(J4/$K$2<=1.001,J4/$K$2,0.6) -> 1.000322 | L4: 0.00023148148 | M4: =IF(L4/$M$2<=1.001,L4/$M$2,0.6) -> 0.010183299 | N4: 0.046527778 | O4: =IF(N4/$O$2<=1.001,N4/$O$2,0.6) -> 0.99727115 | P4: 0.043206019 | Q4: =IF(P4/$Q$2<=1.001,P4/$Q$2,0.6) -> 1 | R4: =AVERAGE(G4,I4,K4,M4,Table1[[#This Row],[%Conexión5]],Table1[[#This Row],[%Conexión6]])*5 -> 3.3252661 | S4: 1 | T4: {=_xlfn.IFS(Table1[[#This Row],[Grupo]]=1,Sheet2!$B$1,Table1[[#This Row],[Grupo]]=2,Sheet2!$B$2,Table1[[#This Row],[Grupo]]=3,Sheet2!$B$3,Table1[[#This Row],[Grupo]]=4,Sheet2!$B$4,Table1[[#This Row],[Grupo]]=5,Sheet2!$B$5,Table1[[#This Row],[Grupo]]=6,Sheet2!$B$6,Table1[[#This Row],[Grupo]]=7,Sheet2!$B$7,Table1[[#This Row],[Grupo]]="","--")} -> Gesto correspondiente a la palabra "Tortuga" en el lenguaje de señas colombiano | U4: 4.9 | V4: 3.6 | W4: 3 | X4: 3.3 | Y4: 1 | Z4: 1.7 | AA4: =AVERAGE(Table1[[#This Row],[Operaciones sobre piezas (Semana 2) ]:[Escaneo de partes anatómicas (Semana 6) ]])*0.7+Table1[[#This Row],[Asistencia]]*0.3 -> 2.7615798 | AB4: 0.041157407 | AC4: =IF(AB4/$AC$2<=1.01,AB4/$AC$2,0.6) -> 1 | AD4: 0.037384259 | AE4: =IF(AD4/$AE$2<=1.01,AD4/$AE$2,0.6) -> 0.99599137 | AF4: 0.038368056 | AG4: 1 | AH4: 0.014722222 | AI4: =IF(AH4/$AI$2<=1.01,AH4/$AI$2,0.6) -> 1 | AJ4: 0.035925926 | AK4: =IF(AJ4/$AK$2<=1.01,AJ4/$AK$2,0.6) -> 1 | AL4: 0.010462963 | AM4: =IF(AL4/$AM$2<=1.01,AL4/$AM$2,0.6) -> 0.34890004 | AN4: =AVERAGE(AC4,AE4,AG4,AI4,AK4,AM4)*5 -> 4.4540762 | AO4: 5 | AP4: 3 | AQ4: =Table1[[#This Row],[Asistencia 2o Corte]]*0.3+AVERAGE(Table1[[#This Row],[Tarea:Introducción a 3DSlicer (Semana 8) (Real)]:[Tarea:Segmentación Manual y Semi-Automática (Semana 10) (Real)]])*0.7 -> 4.1362229 | AU4: 0.036979167 | AV4: =IF(AU4/$AV$2<=1.01,AU4/$AV$2,0.6) -> 0.99594763 | AW4: 0.032650463 | AX4: =IF(AW4/$AX$2<=1.01,AW4/$AX$2,0.6) -> 1 | AY4: 0.036481481 | AZ4: =IF(AY4/$AZ$2<=1.01,AY4/$AZ$2,0.6) -> 1.0035021 | BA4: 0.032673611 | BB4: =IF(BA4/$BB$2<=1.01,BA4/$BB$2,0.6) -> 0.95922528 | BF4: https://oicampo-uao.github.io/academics/CABD/stl_final/Pierna-1.mix | BH4: =AVERAGE(AV4,AX4,AZ4,BB4)*5 -> 4.9483437 | BI4: 4.4 | BJ4: 3.8 | BK4: 1.9 | BL4: 2.8 | BM4: 3.8 | BN4: =AVERAGE(Table1[[#This Row],[Tarea:Impresión 3D (Semana 13) (Real)]:[Tarea:Evaluación Final Sincrónica (Semana 17) (Real)]])*0.7+Table1[[#This Row],[nota asistencia]]*0.3 -> 3.8225031 | BO4: =AVERAGE(AA4,AQ4,BN4) -> 3.5734353
A5: 2 | B5: CABRERA TORO | C5: NICOLAS | D5: 1104804719 | E5: nicolas.cabrera@uao.edu.co | F5: 0.034641204 | G5: =IF(F5/$G$2<=1.001,F5/$G$2,0.6) -> 0.6 | H5: 0.039178241 | I5: =IF(H5/$I$2<=1.001,H5/$I$2,0.6) -> 0.98487053 | J5: 0.035856481 | K5: =IF(J5/$K$2<=1.001,J5/$K$2,0.6) -> 0.99742434 | L5: 0.019652778 | M5: =IF(L5/$M$2<=1.001,L5/$M$2,0.6) -> 0.86456212 | N5: 0 | O5: =IF(N5/$O$2<=1.001,N5/$O$2,0.6) -> 0 | P5: 0.039768519 | Q5: =IF(P5/$Q$2<=1.001,P5/$Q$2,0.6) -> 0.92043932 | R5: =AVERAGE(G5,I5,K5,M5,Table1[[#This Row],[%Conexión5]],Table1[[#This Row],[%Conexión6]])*5 -> 3.6394136 | S5: 4 | T5: {=_xlfn.IFS(Table1[[#This Row],[Grupo]]=1,Sheet2!$B$1,Table1[[#This Row],[Grupo]]=2,Sheet2!$B$2,Table1[[#This Row],[Grupo]]=3,Sheet2!$B$3,Table1[[#This Row],[Grupo]]=4,Sheet2!$B$4,Table1[[#This Row],[Grupo]]=5,Sheet2!$B$5,Table1[[#This Row],[Grupo]]=6,Sheet2!$B$6,Table1[[#This Row],[Grupo]]=7,Sheet2!$B$7,Table1[[#This Row],[Grupo]]="","--")} -> Gesto correspondiente a la palabra "Durazno" en el lenguaje de señas colombiano | U5: 5 | V5: 4.9 | W5: 5 | X5: 3.3 | Y5: 5 | Z5: 4.5 | AA5: =AVERAGE(Table1[[#This Row],[Operaciones sobre piezas (Semana 2) ]:[Escaneo de partes anatómicas (Semana 6) ]])*0.7+Table1[[#This Row],[Asistencia]]*0.3 -> 4.2698241 | AB5: 0.040914352 | AC5: =IF(AB5/$AC$2<=1.01,AB5/$AC$2,0.6) -> 0.99409449 | AD5: 0.016608796 | AE5: =IF(AD5/$AE$2<=1.01,AD5/$AE$2,0.6) -> 0.44249152 | AF5: 0.03494213 | AG5: =IF(AF5/$AG$2<=1.01,AF5/$AG$2,0.6) -> 0.93092815 | AH5: 0.014722222 | AI5: =IF(AH5/$AI$2<=1.01,AH5/$AI$2,0.6) -> 1 | AJ5: 0.013819444 | AK5: =IF(AJ5/$AK$2<=1.01,AJ5/$AK$2,0.6) -> 0.38466495 | AL5: 0.010462963 | AM5: =IF(AL5/$AM$2<=1.01,AL5/$AM$2,0.6) -> 0.34890004 | AN5: =AVERAGE(AC5,AE5,AG5,AI5,AK5,AM5)*5 -> 3.417566 | AO5: 5 | AP5: 3.8 | AQ5: =Table1[[#This Row],[Asistencia 2o Corte]]*0.3+AVERAGE(Table1[[#This Row],[Tarea:Introducción a 3DSlicer (Semana 8) (Real)]:[Tarea:Segmentación Manual y Semi-Automática (Semana 10) (Real)]])*0.7 -> 4.1052698 | AU5: 0.029548611 | AV5: =IF(AU5/$AV$2<=1.01,AU5/$AV$2,0.6) -> 0.79582294 | AW5: 0.032650463 | AX5: =IF(AW5/$AX$2<=1.01,AW5/$AX$2,0.6) -> 1 | AY5: 0.023009259 | AZ5: =IF(AY5/$AZ$2<=1.01,AY5/$AZ$2,0.6) -> 0.63291945 | BA5: 3.4722222e-05 | BB5: =IF(BA5/$BB$2<=1.01,BA5/$BB$2,0.6) -> 0.001019368 | BF5: https://oicampo-uao.github.io/academics/CABD/stl_final/Femur-2.mix | BH5: =AVERAGE(AV5,AX5,AZ5,BB5)*5 -> 3.0372022 | BI5: 5 | BJ5: 4.4 | BK5: 4.8 | BL5: 4.8 | BM5: 0.8 | BN5: =AVERAGE(Table1[[#This Row],[Tarea:Impresión 3D (Semana 13) (Real)]:[Tarea:Evaluación Final Sincrónica (Semana 17) (Real)]])*0.7+Table1[[#This Row],[nota asistencia]]*0.3 -> 3.6831607 | BO5: =AVERAGE(AA5,AQ5,BN5) -> 4.0194182
A6: 3 | B6: CALVO ARCE | C6: ANDRES FELIPE | D6: 1109542109 | E6: andres_felipe.calvo@uao.edu.co | F6: 0.016481481 | G6: =IF(F6/$G$2<=1.001,F6/$G$2,0.6) -> 0.94492369 | H6: 0.038530093 | I6: =IF(H6/$I$2<=1.001,H6/$I$2,0.6) -> 0.96857725 | J6: 0.035821759 | K6: =IF(J6/$K$2<=1.001,J6/$K$2,0.6) -> 0.99645847 | L6: 0.0010648148 | M6: =IF(L6/$M$2<=1.001,L6/$M$2,0.6) -> 0.046843177 | N6: 0.044270833 | O6: =IF(N6/$O$2<=1.001,N6/$O$2,0.6) -> 0.94889606 | P6: 0.039861111 | Q6: =IF(P6/$Q$2<=1.001,P6/$Q$2,0.6) -> 0.92258237 | R6: =AVERAGE(G6,I6,K6,M6,Table1[[#This Row],[%Conexión5]],Table1[[#This Row],[%Conexión6]])*5 -> 4.0235675 | S6: 1 | T6: {=_xlfn.IFS(Table1[[#This Row],[Grupo]]=1,Sheet2!$B$1,Table1[[#This Row],[Grupo]]=2,Sheet2!$B$2,Table1[[#This Row],[Grupo]]=3,Sheet2!$B$3,Table1[[#This Row],[Grupo]]=4,Sheet2!$B$4,Table1[[#This Row],[Grupo]]=5,Sheet2!$B$5,Table1[[#This Row],[Grupo]]=6,Sheet2!$B$6,Table1[[#This Row],[Grupo]]=7,Sheet2!$B$7,Table1[[#This Row],[Grupo]]="","--")} -> Gesto correspondiente a la palabra "Tortuga" en el lenguaje de señas colombiano | U6: 0 | V6: 3.9 | W6: 4.8 | X6: 1.1 | Y6: 2 | Z6: 1.7 | AA6: =AVERAGE(Table1[[#This Row],[Operaciones sobre piezas (Semana 2) ]:[Escaneo de partes anatómicas (Semana 6) ]])*0.7+Table1[[#This Row],[Asistencia]]*0.3 -> 3.0970703 | AB6: 0.038101852 | AC6: =IF(AB6/$AC$2<=1.01,AB6/$AC$2,0.6) -> 0.92575928 | AD6: 0 | AE6: =IF(AD6/$AE$2<=1.01,AD6/$AE$2,0.6) -> 0 | AF6: 0.03724537 | AG6: =IF(AF6/$AG$2<=1.01,AF6/$AG$2,0.6) -> 0.99229109 | AH6: 0.014722222 | AI6: =IF(AH6/$AI$2<=1.01,AH6/$AI$2,0.6) -> 1 | AJ6: 0.035925926 | AK6: =IF(AJ6/$AK$2<=1.01,AJ6/$AK$2,0.6) -> 1 | AL6: 0.011041667 | AM6: =IF(AL6/$AM$2<=1.01,AL6/$AM$2,0.6) -> 0.36819761 | AN6: =AVERAGE(AC6,AE6,AG6,AI6,AK6,AM6)*5 -> 3.5718733 | AO6: 5 | AP6: 2.5 | AQ6: =Table1[[#This Row],[Asistencia 2o Corte]]*0.3+AVERAGE(Table1[[#This Row],[Tarea:Introducción a 3DSlicer (Semana 8) (Real)]:[Tarea:Segmentación Manual y Semi-Automática (Semana 10) (Real)]])*0.7 -> 3.696562 | AT6: https://www.kaggle.com/datasets/adarshsng/heart-mri-image-dataset-left-atrial-segmentation/data | AU6: 0.036736111 | AV6: =IF(AU6/$AV$2<=1.01,AU6/$AV$2,0.6) -> 0.9894015 | AW6: 0.032569444 | AX6: =IF(AW6/$AX$2<=1.01,AW6/$AX$2,0.6) -> 0.99751861 | AY6: 0.036331019 | AZ6: =IF(AY6/$AZ$2<=1.01,AY6/$AZ$2,0.6) -> 0.99936326 | BA6: 0.033553241 | BB6: =IF(BA6/$BB$2<=1.01,BA6/$BB$2,0.6) -> 0.98504927 | BD6: https://drive.google.com/file/d/1UKYI8aEgFPXYCVomvusbK0FEXj_C21qt/view?usp=sharing | BF6: https://oicampo-uao.github.io/academics/CABD/stl_final/Mandibula-1.stl | BH6: =AVERAGE(AV6,AX6,AZ6,BB6)*5 -> 4.9641658 | BI6: 4.4 | BJ6: 3.8 | BK6: 0 | BL6: 0 | BM6: 3.4 | BN6: =AVERAGE(Table1[[#This Row],[Tarea:Impresión 3D (Semana 13) (Real)]:[Tarea:Evaluación Final Sincrónica (Semana 17) (Real)]])*0.7+Table1[[#This Row],[nota asistencia]]*0.3 -> 3.1132497 | BO6: =AVERAGE(AA6,AQ6,BN6) -> 3.302294
A7: 5 | B7: CASTILLO SALAZAR | C7: JUAN MANUEL | D7: 1113978874 | E7: juan_man.castillo@uao.edu.co | F7: 0.01744213 | G7: =IF(F7/$G$2<=1.001,F7/$G$2,0.6) -> 1 | H7: 0.039814815 | I7: =IF(H7/$I$2<=1.001,H7/$I$2,0.6) -> 1.0008729 | J7: 0.035960648 | K7: =IF(J7/$K$2<=1.001,J7/$K$2,0.6) -> 1.000322 | L7: 0.021203704 | M7: =IF(L7/$M$2<=1.001,L7/$M$2,0.6) -> 0.93279022 | N7: 0.046666667 | O7: =IF(N7/$O$2<=1.001,N7/$O$2,0.6) -> 1.0002481 | P7: 0.043206019 | Q7: =IF(P7/$Q$2<=1.001,P7/$Q$2,0.6) -> 1 | R7: =AVERAGE(G7,I7,K7,M7,Table1[[#This Row],[%Conexión5]],Table1[[#This Row],[%Conexión6]])*5 -> 4.9451943 | S7: 4 | T7: {=_xlfn.IFS(Table1[[#This Row],[Grupo]]=1,Sheet2!$B$1,Table1[[#This Row],[Grupo]]=2,Sheet2!$B$2,Table1[[#This Row],[Grupo]]=3,Sheet2!$B$3,Table1[[#This Row],[Grupo]]=4,Sheet2!$B$4,Table1[[#This Row],[Grupo]]=5,Sheet2!$B$5,Table1[[#This Row],[Grupo]]=6,Sheet2!$B$6,Table1[[#This Row],[Grupo]]=7,Sheet2!$B$7,Table1[[#This Row],[Grupo]]="","--")} -> Gesto correspondiente a la palabra "Durazno" en el lenguaje de señas colombiano | U7: 5 | V7: 4.9 | W7: 5 | X7: 5 | Y7: 5 | Z7: 4.5 | AA7: =AVERAGE(Table1[[#This Row],[Operaciones sobre piezas (Semana 2) ]:[Escaneo de partes anatómicas (Semana 6) ]])*0.7+Table1[[#This Row],[Asistencia]]*0.3 -> 4.8995583 | AB7: 0.039328704 | AC7: =IF(AB7/$AC$2<=1.01,AB7/$AC$2,0.6) -> 0.95556805 | AD7: 0.037384259 | AE7: =IF(AD7/$AE$2<=1.01,AD7/$AE$2,0.6) -> 0.99599137 | AF7: 0.038368056 | AG7: 1 | AH7: 0.014722222 | AI7: =IF(AH7/$AI$2<=1.01,AH7/$AI$2,0.6) -> 1 | AJ7: 0.035509259 | AK7: =IF(AJ7/$AK$2<=1.01,AJ7/$AK$2,0.6) -> 0.98840206 | AL7: 0.010462963 | AM7: =IF(AL7/$AM$2<=1.01,AL7/$AM$2,0.6) -> 0.34890004 | AN7: =AVERAGE(AC7,AE7,AG7,AI7,AK7,AM7)*5 -> 4.4073846 | AO7: 5 | AP7: 4.3 | AQ7: =Table1[[#This Row],[Asistencia 2o Corte]]*0.3+AVERAGE(Table1[[#This Row],[Tarea:Introducción a 3DSlicer (Semana 8) (Real)]:[Tarea:Segmentación Manual y Semi-Automática (Semana 10) (Real)]])*0.7 -> 4.5772154 | AU7: 0.03712963 | AV7: =IF(AU7/$AV$2<=1.01,AU7/$AV$2,0.6) -> 1 | AW7: 0.027037037 | AX7: =IF(AW7/$AX$2<=1.01,AW7/$AX$2,0.6) -> 0.82807515 | AY7: 0.036481481 | AZ7: =IF(AY7/$AZ$2<=1.01,AY7/$AZ$2,0.6) -> 1.0035021 | BA7: 0.033090278 | BB7: =IF(BA7/$BB$2<=1.01,BA7/$BB$2,0.6) -> 0.9714577 | BF7: https://oicampo-uao.github.io/academics/CABD/stl_final/Torax-1.mix | BH7: =AVERAGE(AV7,AX7,AZ7,BB7)*5 -> 4.7537936 | BI7: 5 | BJ7: 4.4 | BK7: 4.8 | BL7: 4.8 | BM7: 5 | BN7: =AVERAGE(Table1[[#This Row],[Tarea:Impresión 3D (Semana 13) (Real)]:[Tarea:Evaluación Final Sincrónica (Semana 17) (Real)]])*0.7+Table1[[#This Row],[nota asistencia]]*0.3 -> 4.7861381 | BO7: =AVERAGE(AA7,AQ7,BN7) -> 4.7543039
A8: 6 | B8: CORREA SEGURA | C8: FERNANDO ENRIQUE | D8: 1007560675 | E8: fernando_enr.correa@uao.edu.co | F8: 0.00052083333 | G8: =IF(F8/$G$2<=1.001,F8/$G$2,0.6) -> 0.02986065 | H8: 0.039074074 | I8: =IF(H8/$I$2<=1.001,H8/$I$2,0.6) -> 0.98225196 | J8: 0.035763889 | K8: =IF(J8/$K$2<=1.001,J8/$K$2,0.6) -> 0.99484868 | L8: 0.018090278 | M8: =IF(L8/$M$2<=1.001,L8/$M$2,0.6) -> 0.79582485 | N8: 0.046388889 | O8: =IF(N8/$O$2<=1.001,N8/$O$2,0.6) -> 0.99429422 | P8: 0.041805556 | Q8: =IF(P8/$Q$2<=1.001,P8/$Q$2,0.6) -> 0.96758639 | R8: =AVERAGE(G8,I8,K8,M8,Table1[[#This Row],[%Conexión5]],Table1[[#This Row],[%Conexión6]])*5 -> 3.9705556 | S8: 3 | T8: {=_xlfn.IFS(Table1[[#This Row],[Grupo]]=1,Sheet2!$B$1,Table1[[#This Row],[Grupo]]=2,Sheet2!$B$2,Table1[[#This Row],[Grupo]]=3,Sheet2!$B$3,Table1[[#This Row],[Grupo]]=4,Sheet2!$B$4,Table1[[#This Row],[Grupo]]=5,Sheet2!$B$5,Table1[[#This Row],[Grupo]]=6,Sheet2!$B$6,Table1[[#This Row],[Grupo]]=7,Sheet2!$B$7,Table1[[#This Row],[Grupo]]="","--")} -> Gesto correspondiente a la palabra "Oveja" en el lenguaje de señas colombiano | U8: 5 | V8: 5 | W8: 4 | X8: 5 | Y8: 5 | Z8: 4.5 | AA8: =AVERAGE(Table1[[#This Row],[Operaciones sobre piezas (Semana 2) ]:[Escaneo de partes anatómicas (Semana 6) ]])*0.7+Table1[[#This Row],[Asistencia]]*0.3 -> 4.4811667 | AB8: 0.036736111 | AC8: =IF(AB8/$AC$2<=1.01,AB8/$AC$2,0.6) -> 0.89257593 | AD8: 0.032986111 | AE8: =IF(AD8/$AE$2<=1.01,AD8/$AE$2,0.6) -> 0.87881591 | AF8: 0.036724537 | AG8: =IF(AF8/$AG$2<=1.01,AF8/$AG$2,0.6) -> 0.97841505 | AH8: 0.014722222 | AI8: =IF(AH8/$AI$2<=1.01,AH8/$AI$2,0.6) -> 1 | AJ8: 0.035925926 | AK8: =IF(AJ8/$AK$2<=1.01,AJ8/$AK$2,0.6) -> 1 | AL8: 0.026909722 | AM8: =IF(AL8/$AM$2<=1.01,AL8/$AM$2,0.6) -> 0.89733694 | AN8: =AVERAGE(AC8,AE8,AG8,AI8,AK8,AM8)*5 -> 4.7059532 | AO8: 0 | AP8: 2.6 | AQ8: =Table1[[#This Row],[Asistencia 2o Corte]]*0.3+AVERAGE(Table1[[#This Row],[Tarea:Introducción a 3DSlicer (Semana 8) (Real)]:[Tarea:Segmentación Manual y Semi-Automática (Semana 10) (Real)]])*0.7 -> 2.321786 | AS8: CT Chest: Segmentación automática y comparar con segmentación manual de 3 órganos o tejidos | AT8: Tumor Cerebral | AU8: 0.037141204 | AV8: =IF(AU8/$AV$2<=1.01,AU8/$AV$2,0.6) -> 1.0003117 | AW8: 0.032650463 | AX8: =IF(AW8/$AX$2<=1.01,AW8/$AX$2,0.6) -> 1 | AY8: 0.034965278 | AZ8: =IF(AY8/$AZ$2<=1.01,AY8/$AZ$2,0.6) -> 0.96179561 | BA8: 0.0340625 | BB8: =IF(BA8/$BB$2<=1.01,BA8/$BB$2,0.6) -> 1 | BC8: CT-Liver Fémur izq. | BD8: Archivo Sample de 3D Slicer: CBCTDentalSurgery: Pre Dental Surgery | BE8: https://drive.google.com/file/d/1PPehENxnv1mJwFY7OLhcEx8tc1k1CoNw/view?usp=sharing | BF8: https://oicampo-uao.github.io/academics/CABD/stl_final/Femur-3.mix | BH8: =AVERAGE(AV8,AX8,AZ8,BB8)*5 -> 4.9526342 | BI8: 5 | BJ8: 4.7 | BK8: 4.8 | BL8: 4.3 | BM8: 3.4 | BN8: =AVERAGE(Table1[[#This Row],[Tarea:Impresión 3D (Semana 13) (Real)]:[Tarea:Evaluación Final Sincrónica (Semana 17) (Real)]])*0.7+Table1[[#This Row],[nota asistencia]]*0.3 -> 4.5937902 | BO8: =AVERAGE(AA8,AQ8,BN8) -> 3.7989143
A9: 7 | B9: DELGADO MATABANCHOY | C9: JUAN SEBASTIAN | D9: 1004189893 | E9: juan_s.delgado_m@uao.edu.co | F9: 0 | G9: =IF(F9/$G$2<=1.001,F9/$G$2,0.6) -> 0 | H9: 0 | I9: =IF(H9/$I$2<=1.001,H9/$I$2,0.6) -> 0 | J9: 0 | K9: =IF(J9/$K$2<=1.001,J9/$K$2,0.6) -> 0 | L9: 0 | M9: =IF(L9/$M$2<=1.001,L9/$M$2,0.6) -> 0 | N9: 0 | O9: =IF(N9/$O$2<=1.001,N9/$O$2,0.6) -> 0 | P9: 0 | Q9: =IF(P9/$Q$2<=1.001,P9/$Q$2,0.6) -> 0 | R9: =AVERAGE(G9,I9,K9,M9,Table1[[#This Row],[%Conexión5]],Table1[[#This Row],[%Conexión6]])*5 -> 0 | T9: {=_xlfn.IFS(Table1[[#This Row],[Grupo]]=1,Sheet2!$B$1,Table1[[#This Row],[Grupo]]=2,Sheet2!$B$2,Table1[[#This Row],[Grupo]]=3,Sheet2!$B$3,Table1[[#This Row],[Grupo]]=4,Sheet2!$B$4,Table1[[#This Row],[Grupo]]=5,Sheet2!$B$5,Table1[[#This Row],[Grupo]]=6,Sheet2!$B$6,Table1[[#This Row],[Grupo]]=7,Sheet2!$B$7,Table1[[#This Row],[Grupo]]="","--")} -> -- | U9: 0 | V9: 0 | W9: 0 | X9: 0 | Y9: 0 | Z9: 0 | AA9: =AVERAGE(Table1[[#This Row],[Operaciones sobre piezas (Semana 2) ]:[Escaneo de partes anatómicas (Semana 6) ]])*0.7+Table1[[#This Row],[Asistencia]]*0.3 -> 0 | AB9: 0 | AC9: =IF(AB9/$AC$2<=1.01,AB9/$AC$2,0.6) -> 0 | AD9: 0 | AE9: =IF(AD9/$AE$2<=1.01,AD9/$AE$2,0.6) -> 0 | AF9: 0 | AG9: =IF(AF9/$AG$2<=1.01,AF9/$AG$2,0.6) -> 0 | AH9: 0 | AI9: =IF(AH9/$AI$2<=1.01,AH9/$AI$2,0.6) -> 0 | AJ9: 0 | AK9: =IF(AJ9/$AK$2<=1.01,AJ9/$AK$2,0.6) -> 0 | AL9: =IF(AK9/$AK$2<=1.01,AK9/$AK$2,0.6) -> 0 | AM9: =IF(AL9/$AM$2<=1.01,AL9/$AM$2,0.6) -> 0 | AN9: =AVERAGE(AC9,AE9,AG9,AI9,AK9,AM9)*5 -> 0 | AO9: 0 | AP9: 0 | AQ9: =Table1[[#This Row],[Asistencia 2o Corte]]*0.3+AVERAGE(Table1[[#This Row],[Tarea:Introducción a 3DSlicer (Semana 8) (Real)]:[Tarea:Segmentación Manual y Semi-Automática (Semana 10) (Real)]])*0.7 -> 0 | AU9: 0 | AV9: =IF(AU9/$AV$2<=1.01,AU9/$AV$2,0.6) -> 0 | AW9: 0 | AX9: =IF(AW9/$AX$2<=1.01,AW9/$AX$2,0.6) -> 0 | AY9: 0 | AZ9: =IF(AY9/$AZ$2<=1.01,AY9/$AZ$2,0.6) -> 0 | BA9: 0 | BB9: =IF(BA9/$BB$2<=1.01,BA9/$BB$2,0.6) -> 0 | BF9: https://oicampo-uao.github.io/academics/CABD/stl_final/Mandibula-2.stl | BH9: =AVERAGE(AV9,AX9,AZ9,BB9)*5 -> 0 | BI9: 0 | BJ9: 0 | BK9: 0 | BL9: 0 | BM9: 0 | BN9: =AVERAGE(Table1[[#This Row],[Tarea:Impresión 3D (Semana 13) (Real)]:[Tarea:Evaluación Final Sincrónica (Semana 17) (Real)]])*0.7+Table1[[#This Row],[nota asistencia]]*0.3 -> 0 | BO9: =AVERAGE(AA9,AQ9,BN9) -> 0
A10: 8 | B10: DIAGO VALDERRAMA | C10: MIGUEL ANDRES | D10: 1005892878 | E10: miguel.diago@uao.edu.co | F10: 0.01744213 | G10: =IF(F10/$G$2<=1.001,F10/$G$2,0.6) -> 1 | H10: 0.039814815 | I10: =IF(H10/$I$2<=1.001,H10/$I$2,0.6) -> 1.0008729 | J10: 0.035960648 | K10: =IF(J10/$K$2<=1.001,J10/$K$2,0.6) -> 1.000322 | L10: 0.018935185 | M10: =IF(L10/$M$2<=1.001,L10/$M$2,0.6) -> 0.83299389 | N10: 0.045497685 | O10: =IF(N10/$O$2<=1.001,N10/$O$2,0.6) -> 0.97519226 | P10: 0.041145833 | Q10: =IF(P10/$Q$2<=1.001,P10/$Q$2,0.6) -> 0.95231717 | R10: =AVERAGE(G10,I10,K10,M10,Table1[[#This Row],[%Conexión5]],Table1[[#This Row],[%Conexión6]])*5 -> 4.8014151 | S10: 5 | T10: {=_xlfn.IFS(Table1[[#This Row],[Grupo]]=1,Sheet2!$B$1,Table1[[#This Row],[Grupo]]=2,Sheet2!$B$2,Table1[[#This Row],[Grupo]]=3,Sheet2!$B$3,Table1[[#This Row],[Grupo]]=4,Sheet2!$B$4,Table1[[#This Row],[Grupo]]=5,Sheet2!$B$5,Table1[[#This Row],[Grupo]]=6,Sheet2!$B$6,Table1[[#This Row],[Grupo]]=7,Sheet2!$B$7,Table1[[#This Row],[Grupo]]="","--")} -> Gesto correspondiente a la palabra "Caracol" en el lenguaje de señas colombiano | U10: 5 | V10: 4.5 | W10: 5 | X10: 3.3 | Y10: 5 | Z10: 4.5 | AA10: =AVERAGE(Table1[[#This Row],[Operaciones sobre piezas (Semana 2) ]:[Escaneo de partes anatómicas (Semana 6) ]])*0.7+Table1[[#This Row],[Asistencia]]*0.3 -> 4.5624245 | AB10: 0.039305556 | AC10: =IF(AB10/$AC$2<=1.01,AB10/$AC$2,0.6) -> 0.95500562 | AD10: 0.037384259 | AE10: =IF(AD10/$AE$2<=1.01,AD10/$AE$2,0.6) -> 0.99599137 | AF10: 0.029363426 | AG10: =IF(AF10/$AG$2<=1.01,AF10/$AG$2,0.6) -> 0.78230034 | AH10: 0.014722222 | AI10: =IF(AH10/$AI$2<=1.01,AH10/$AI$2,0.6) -> 1 | AJ10: 0.035925926 | AK10: =IF(AJ10/$AK$2<=1.01,AJ10/$AK$2,0.6) -> 1 | AL10: 0.012233796 | AM10: =IF(AL10/$AM$2<=1.01,AL10/$AM$2,0.6) -> 0.4079506 | AN10: =AVERAGE(AC10,AE10,AG10,AI10,AK10,AM10)*5 -> 4.2843733 | AO10: 5 | AP10: 0 | AQ10: =Table1[[#This Row],[Asistencia 2o Corte]]*0.3+AVERAGE(Table1[[#This Row],[Tarea:Introducción a 3DSlicer (Semana 8) (Real)]:[Tarea:Segmentación Manual y Semi-Automática (Semana 10) (Real)]])*0.7 -> 3.035312 | AU10: 0.03712963 | AV10: =IF(AU10/$AV$2<=1.01,AU10/$AV$2,0.6) -> 1 | AW10: 0.032650463 | AX10: =IF(AW10/$AX$2<=1.01,AW10/$AX$2,0.6) -> 1 | AY10: 0.036319444 | AZ10: =IF(AY10/$AZ$2<=1.01,AY10/$AZ$2,0.6) -> 0.99904489 | BA10: 0.034074074 | BB10: =IF(BA10/$BB$2<=1.01,BA10/$BB$2,0.6) -> 1.0003398 | BF10: https://oicampo-uao.github.io/academics/CABD/stl_final/Torax-2.mix | BH10: =AVERAGE(AV10,AX10,AZ10,BB10)*5 -> 4.9992308 | BI10: 4.4 | BJ10: 3.5 | BK10: 4.3 | BL10: 3.8 | BM10: 3 | BN10: =AVERAGE(Table1[[#This Row],[Tarea:Impresión 3D (Semana 13) (Real)]:[Tarea:Evaluación Final Sincrónica (Semana 17) (Real)]])*0.7+Table1[[#This Row],[nota asistencia]]*0.3 -> 4.1597693 | BO10: =AVERAGE(AA10,AQ10,BN10) -> 3.9191686
A11: 9 | B11: FERNANDEZ VELASCO | C11: ILSE | D11: 1107837304 | E11: ilse.fernandez@uao.edu.co | F11: 0.038090278 | G11: =IF(F11/$G$2<=1.001,F11/$G$2,0.6) -> 0.6 | H11: 0.038541667 | I11: =IF(H11/$I$2<=1.001,H11/$I$2,0.6) -> 0.9688682 | J11: 0.033229167 | K11: =IF(J11/$K$2<=1.001,J11/$K$2,0.6) -> 0.92433999 | L11: 0.0051157407 | M11: =IF(L11/$M$2<=1.001,L11/$M$2,0.6) -> 0.22505092 | N11: 0.044849537 | O11: =IF(N11/$O$2<=1.001,N11/$O$2,0.6) -> 0.96129993 | P11: 0.039386574 | Q11: =IF(P11/$Q$2<=1.001,P11/$Q$2,0.6) -> 0.91159925 | R11: =AVERAGE(G11,I11,K11,M11,Table1[[#This Row],[%Conexión5]],Table1[[#This Row],[%Conexión6]])*5 -> 3.8259652 | S11: 5 | T11: {=_xlfn.IFS(Table1[[#This Row],[Grupo]]=1,Sheet2!$B$1,Table1[[#This Row],[Grupo]]=2,Sheet2!$B$2,Table1[[#This Row],[Grupo]]=3,Sheet2!$B$3,Table1[[#This Row],[Grupo]]=4,Sheet2!$B$4,Table1[[#This Row],[Grupo]]=5,Sheet2!$B$5,Table1[[#This Row],[Grupo]]=6,Sheet2!$B$6,Table1[[#This Row],[Grupo]]=7,Sheet2!$B$7,Table1[[#This Row],[Grupo]]="","--")} -> Gesto correspondiente a la palabra "Caracol" en el lenguaje de señas colombiano | U11: 4.8 | V11: 4.1 | W11: 5 | X11: 3.3 | Y11: 5 | Z11: 4.5 | AA11: =AVERAGE(Table1[[#This Row],[Operaciones sobre piezas (Semana 2) ]:[Escaneo de partes anatómicas (Semana 6) ]])*0.7+Table1[[#This Row],[Asistencia]]*0.3 -> 4.2137896 | AB11: 0.038101852 | AC11: =IF(AB11/$AC$2<=1.01,AB11/$AC$2,0.6) -> 0.92575928 | AD11: 0.037384259 | AE11: =IF(AD11/$AE$2<=1.01,AD11/$AE$2,0.6) -> 0.99599137 | AF11: 0.038368056 | AG11: 1 | AH11: 0.014722222 | AI11: =IF(AH11/$AI$2<=1.01,AH11/$AI$2,0.6) -> 1 | AJ11: 0.035752315 | AK11: =IF(AJ11/$AK$2<=1.01,AJ11/$AK$2,0.6) -> 0.99516753 | AL11: 0.022719907 | AM11: =IF(AL11/$AM$2<=1.01,AL11/$AM$2,0.6) -> 0.75762254 | AN11: =AVERAGE(AC11,AE11,AG11,AI11,AK11,AM11)*5 -> 4.7287839 | AO11: 5 | AP11: 3.2 | AQ11: =Table1[[#This Row],[Asistencia 2o Corte]]*0.3+AVERAGE(Table1[[#This Row],[Tarea:Introducción a 3DSlicer (Semana 8) (Real)]:[Tarea:Segmentación Manual y Semi-Automática (Semana 10) (Real)]])*0.7 -> 4.2886352 | AS11: CT Abdomen (panoramix): Segmentación automática y comparar con segmentación manual de 3 órganos | AU11: 0.03712963 | AV11: =IF(AU11/$AV$2<=1.01,AU11/$AV$2,0.6) -> 1 | AW11: 0.032037037 | AX11: =IF(AW11/$AX$2<=1.01,AW11/$AX$2,0.6) -> 0.98121234 | AY11: 0.032731481 | AZ11: =IF(AY11/$AZ$2<=1.01,AY11/$AZ$2,0.6) -> 0.90035021 | BA11: 0.032476852 | BB11: =IF(BA11/$BB$2<=1.01,BA11/$BB$2,0.6) -> 0.95344886 | BC11: CT-Liver Fémur izq. | BD11: Archivo Sample de 3D Slicer: CBCTDentalSurgery: Post Dental Surgery | BE11: https://drive.google.com/file/d/1eKb4I6epI_aJ6toCtHnOaL5-8ep_2Olp/view?usp=sharing | BF11: https://oicampo-uao.github.io/academics/CABD/stl_final/Pierna-2.mix | BH11: =AVERAGE(AV11,AX11,AZ11,BB11)*5 -> 4.7937643 | BI11: 4.4 | BJ11: 3.5 | BK11: 4.3 | BL11: 3.8 | BM11: 3 | BN11: =AVERAGE(Table1[[#This Row],[Tarea:Impresión 3D (Semana 13) (Real)]:[Tarea:Evaluación Final Sincrónica (Semana 17) (Real)]])*0.7+Table1[[#This Row],[nota asistencia]]*0.3 -> 4.0981293 | BO11: =AVERAGE(AA11,AQ11,BN11) -> 4.2001847
A12: 10 | B12: GARCIA BENAVIDES | C12: KTALYNA | D12: 1058932076 | E12: ktalyna.garcia@uao.edu.co | F12: 0.036388889 | G12: =IF(F12/$G$2<=1.001,F12/$G$2,0.6) -> 0.6 | H12: 0.039282407 | I12: =IF(H12/$I$2<=1.001,H12/$I$2,0.6) -> 0.98748909 | J12: 0.035960648 | K12: =IF(J12/$K$2<=1.001,J12/$K$2,0.6) -> 1.000322 | L12: 0.022395833 | M12: =IF(L12/$M$2<=1.001,L12/$M$2,0.6) -> 0.98523422 | N12: 0.046608796 | O12: =IF(N12/$O$2<=1.001,N12/$O$2,0.6) -> 0.99900769 | P12: 0.043206019 | Q12: =IF(P12/$Q$2<=1.001,P12/$Q$2,0.6) -> 1 | R12: =AVERAGE(G12,I12,K12,M12,Table1[[#This Row],[%Conexión5]],Table1[[#This Row],[%Conexión6]])*5 -> 4.6433775 | S12: 7 | T12: {=_xlfn.IFS(Table1[[#This Row],[Grupo]]=1,Sheet2!$B$1,Table1[[#This Row],[Grupo]]=2,Sheet2!$B$2,Table1[[#This Row],[Grupo]]=3,Sheet2!$B$3,Table1[[#This Row],[Grupo]]=4,Sheet2!$B$4,Table1[[#This Row],[Grupo]]=5,Sheet2!$B$5,Table1[[#This Row],[Grupo]]=6,Sheet2!$B$6,Table1[[#This Row],[Grupo]]=7,Sheet2!$B$7,Table1[[#This Row],[Grupo]]="","--")} -> Gesto correspondiente a la palabra "Flor" en el lenguaje de señas colombiano | U12: 4.4 | V12: 4.5 | W12: 4.8 | X12: 1.7 | Y12: 5 | Z12: 4.5 | AA12: =AVERAGE(Table1[[#This Row],[Operaciones sobre piezas (Semana 2) ]:[Escaneo de partes anatómicas (Semana 6) ]])*0.7+Table1[[#This Row],[Asistencia]]*0.3 -> 4.2630132 | AB12: 0.036574074 | AC12: =IF(AB12/$AC$2<=1.01,AB12/$AC$2,0.6) -> 0.88863892 | AD12: 0.036747685 | AE12: =IF(AD12/$AE$2<=1.01,AD12/$AE$2,0.6) -> 0.97903176 | AF12: 0.0081134259 | AG12: =IF(AF12/$AG$2<=1.01,AF12/$AG$2,0.6) -> 0.21615788 | AH12: 0.014722222 | AI12: =IF(AH12/$AI$2<=1.01,AH12/$AI$2,0.6) -> 1 | AJ12: 0.0265625 | AK12: =IF(AJ12/$AK$2<=1.01,AJ12/$AK$2,0.6) -> 0.73936856 | AL12: 0.011678241 | AM12: =IF(AL12/$AM$2<=1.01,AL12/$AM$2,0.6) -> 0.38942493 | AN12: =AVERAGE(AC12,AE12,AG12,AI12,AK12,AM12)*5 -> 3.5105184 | AO12: 5 | AP12: 3.8 | AQ12: =Table1[[#This Row],[Asistencia 2o Corte]]*0.3+AVERAGE(Table1[[#This Row],[Tarea:Introducción a 3DSlicer (Semana 8) (Real)]:[Tarea:Segmentación Manual y Semi-Automática (Semana 10) (Real)]])*0.7 -> 4.1331555 | AS12: CT Cardio: Segmentación automática y comparar con segmentación manual de 3 órganos | AT12: Tumor Cerebral | AU12: 0.03712963 | AV12: =IF(AU12/$AV$2<=1.01,AU12/$AV$2,0.6) -> 1 | AW12: 0.031608796 | AX12: =IF(AW12/$AX$2<=1.01,AW12/$AX$2,0.6) -> 0.96809642 | AY12: 0.035011574 | AZ12: =IF(AY12/$AZ$2<=1.01,AY12/$AZ$2,0.6) -> 0.96306909 | BA12: 0.032465278 | BB12: =IF(BA12/$BB$2<=1.01,BA12/$BB$2,0.6) -> 0.95310907 | BC12: CT-Liver Fémur izq. | BD12: Archivo Sample de 3D Slicer: CBCT- MR Head | BE12: https://drive.google.com/file/d/1s72DbmqHh-D1OgF5ot13C9jgSAeFEf2j/view?usp=sharing | BF12: https://oicampo-uao.github.io/academics/CABD/stl_final/Torax-1.mix | BH12: =AVERAGE(AV12,AX12,AZ12,BB12)*5 -> 4.8553432 | BI12: 4.7 | BJ12: 4.1 | BK12: 4 | BL12: 4.5 | BM12: 1.2 | BN12: =AVERAGE(Table1[[#This Row],[Tarea:Impresión 3D (Semana 13) (Real)]:[Tarea:Evaluación Final Sincrónica (Semana 17) (Real)]])*0.7+Table1[[#This Row],[nota asistencia]]*0.3 -> 4.046603 | BO12: =AVERAGE(AA12,AQ12,BN12) -> 4.1475906
A13: 11 | B13: GARCIA GARCIA | C13: HARRISON | D13: 1110285503 | E13: harrison.garcia@uao.edu.co | F13: 0.017314815 | G13: =IF(F13/$G$2<=1.001,F13/$G$2,0.6) -> 0.99270073 | H13: 0.039189815 | I13: =IF(H13/$I$2<=1.001,H13/$I$2,0.6) -> 0.98516148 | J13: 0 | K13: =IF(J13/$K$2<=1.001,J13/$K$2,0.6) -> 0 | L13: 0 | M13: =IF(L13/$M$2<=1.001,L13/$M$2,0.6) -> 0 | N13: 0.043275463 | O13: =IF(N13/$O$2<=1.001,N13/$O$2,0.6) -> 0.9275614 | P13: 0.04318287 | Q13: =IF(P13/$Q$2<=1.001,P13/$Q$2,0.6) -> 0.99946424 | R13: =AVERAGE(G13,I13,K13,M13,Table1[[#This Row],[%Conexión5]],Table1[[#This Row],[%Conexión6]])*5 -> 3.2540732 | S13: 4 | T13: {=_xlfn.IFS(Table1[[#This Row],[Grupo]]=1,Sheet2!$B$1,Table1[[#This Row],[Grupo]]=2,Sheet2!$B$2,Table1[[#This Row],[Grupo]]=3,Sheet2!$B$3,Table1[[#This Row],[Grupo]]=4,Sheet2!$B$4,Table1[[#This Row],[Grupo]]=5,Sheet2!$B$5,Table1[[#This Row],[Grupo]]=6,Sheet2!$B$6,Table1[[#This Row],[Grupo]]=7,Sheet2!$B$7,Table1[[#This Row],[Grupo]]="","--")} -> Gesto correspondiente a la palabra "Durazno" en el lenguaje de señas colombiano | U13: 5 | V13: 4 | W13: 0.6 | X13: 5 | Y13: 5 | Z13: 4.5 | AA13: =AVERAGE(Table1[[#This Row],[Operaciones sobre piezas (Semana 2) ]:[Escaneo de partes anatómicas (Semana 6) ]])*0.7+Table1[[#This Row],[Asistencia]]*0.3 -> 3.650222 | AB13: 0.037256944 | AC13: =IF(AB13/$AC$2<=1.01,AB13/$AC$2,0.6) -> 0.9052306 | AD13: 0 | AE13: =IF(AD13/$AE$2<=1.01,AD13/$AE$2,0.6) -> 0 | AF13: 0.038368056 | AG13: 1 | AH13: 0.01412037 | AI13: =IF(AH13/$AI$2<=1.01,AH13/$AI$2,0.6) -> 0.9591195 | AJ13: 0.022407407 | AK13: =IF(AJ13/$AK$2<=1.01,AJ13/$AK$2,0.6) -> 0.62371134 | AL13: 0.02787037 | AM13: =IF(AL13/$AM$2<=1.01,AL13/$AM$2,0.6) -> 0.9293709 | AN13: =AVERAGE(AC13,AE13,AG13,AI13,AK13,AM13)*5 -> 3.6811936 | AO13: 5 | AP13: 3.6 | AQ13: =Table1[[#This Row],[Asistencia 2o Corte]]*0.3+AVERAGE(Table1[[#This Row],[Tarea:Introducción a 3DSlicer (Semana 8) (Real)]:[Tarea:Segmentación Manual y Semi-Automática (Semana 10) (Real)]])*0.7 -> 4.1143581 | AS13: CT Cardio: Segmentación automática y comparar con segmentación manual de 3 órganos | AT13: riñones | AU13: 0 | AV13: =IF(AU13/$AV$2<=1.01,AU13/$AV$2,0.6) -> 0 | AW13: 0.032650463 | AX13: =IF(AW13/$AX$2<=1.01,AW13/$AX$2,0.6) -> 1 | AY13: 0.022511574 | AZ13: =IF(AY13/$AZ$2<=1.01,AY13/$AZ$2,0.6) -> 0.61922954 | BA13: 0 | BB13: =IF(BA13/$BB$2<=1.01,BA13/$BB$2,0.6) -> 0 | BC13: CT-Liver Fémur der. | BD13: Archivo Sample de 3D Slicer: CBCTDentalSurgery: Pre Dental Surgery | BE13: https://drive.google.com/file/d/1R8ghynVtHtatpDEnWiEQ90VkaQFdPaFA/view?usp=sharing | BF13: https://oicampo-uao.github.io/academics/CABD/stl_final/Mandibula-1.stl | BG13: https://oicampo-uao.github.io/academics/CABD/stl_final/Femur-1.mix | BH13: =AVERAGE(AV13,AX13,AZ13,BB13)*5 -> 2.0240369 | BI13: 5 | BJ13: 4.4 | BK13: 4.8 | BL13: 4.8 | BM13: 0 | BN13: =AVERAGE(Table1[[#This Row],[Tarea:Impresión 3D (Semana 13) (Real)]:[Tarea:Evaluación Final Sincrónica (Semana 17) (Real)]])*0.7+Table1[[#This Row],[nota asistencia]]*0.3 -> 3.2672111 | BO13: =AVERAGE(AA13,AQ13,BN13) -> 3.6772637
A14: 12 | B14: GONZALEZ PARRA | C14: MARIA PAULA | D14: 1107837413 | E14: maria_p.gonzalez@uao.edu.co | F14: 0 | G14: =IF(F14/$G$2<=1.001,F14/$G$2,0.6) -> 0 | H14: 0.037743056 | I14: =IF(H14/$I$2<=1.001,H14/$I$2,0.6) -> 0.94879255 | J14: 0.035925926 | K14: =IF(J14/$K$2<=1.001,J14/$K$2,0.6) -> 0.99935608 | L14: 0.020636574 | M14: =IF(L14/$M$2<=1.001,L14/$M$2,0.6) -> 0.90784114 | N14: 0 | O14: =IF(N14/$O$2<=1.001,N14/$O$2,0.6) -> 0 | P14: 0.039016204 | Q14: =IF(P14/$Q$2<=1.001,P14/$Q$2,0.6) -> 0.90302706 | R14: =AVERAGE(G14,I14,K14,M14,Table1[[#This Row],[%Conexión5]],Table1[[#This Row],[%Conexión6]])*5 -> 3.132514 | S14: 2 | T14: {=_xlfn.IFS(Table1[[#This Row],[Grupo]]=1,Sheet2!$B$1,Table1[[#This Row],[Grupo]]=2,Sheet2!$B$2,Table1[[#This Row],[Grupo]]=3,Sheet2!$B$3,Table1[[#This Row],[Grupo]]=4,Sheet2!$B$4,Table1[[#This Row],[Grupo]]=5,Sheet2!$B$5,Table1[[#This Row],[Grupo]]=6,Sheet2!$B$6,Table1[[#This Row],[Grupo]]=7,Sheet2!$B$7,Table1[[#This Row],[Grupo]]="","--")} -> Gesto correspondiente a la palabra "Ratón" en el lenguaje de señas colombiano | U14: 0 | V14: 3.9 | W14: 5 | X14: 3.3 | Y14: 5 | Z14: 4.5 | AA14: =AVERAGE(Table1[[#This Row],[Operaciones sobre piezas (Semana 2) ]:[Escaneo de partes anatómicas (Semana 6) ]])*0.7+Table1[[#This Row],[Asistencia]]*0.3 -> 3.9777542 | AB14: 0.038090278 | AC14: =IF(AB14/$AC$2<=1.01,AB14/$AC$2,0.6) -> 0.92547807 | AD14: 0.037384259 | AE14: =IF(AD14/$AE$2<=1.01,AD14/$AE$2,0.6) -> 0.99599137 | AF14: 0.028125 | AG14: =IF(AF14/$AG$2<=1.01,AF14/$AG$2,0.6) -> 0.7493062 | AH14: 0.014722222 | AI14: =IF(AH14/$AI$2<=1.01,AH14/$AI$2,0.6) -> 1 | AJ14: 0 | AK14: =IF(AJ14/$AK$2<=1.01,AJ14/$AK$2,0.6) -> 0 | AL14: 0.02994213 | AM14: =IF(AL14/$AM$2<=1.01,AL14/$AM$2,0.6) -> 0.99845619 | AN14: =AVERAGE(AC14,AE14,AG14,AI14,AK14,AM14)*5 -> 3.8910265 | AO14: 5 | AP14: 0 | AQ14: =Table1[[#This Row],[Asistencia 2o Corte]]*0.3+AVERAGE(Table1[[#This Row],[Tarea:Introducción a 3DSlicer (Semana 8) (Real)]:[Tarea:Segmentación Manual y Semi-Automática (Semana 10) (Real)]])*0.7 -> 2.917308 | AU14: 0.029537037 | AV14: =IF(AU14/$AV$2<=1.01,AU14/$AV$2,0.6) -> 0.79551122 | AW14: 0.032650463 | AX14: =IF(AW14/$AX$2<=1.01,AW14/$AX$2,0.6) -> 1 | AY14: 0.015347222 | AZ14: =IF(AY14/$AZ$2<=1.01,AY14/$AZ$2,0.6) -> 0.42215855 | BA14: 0 | BB14: =IF(BA14/$BB$2<=1.01,BA14/$BB$2,0.6) -> 0 | BF14: https://oicampo-uao.github.io/academics/CABD/stl_final/Pierna-2.mix | BG14: https://oicampo-uao.github.io/academics/CABD/stl_final/Femur-1.mix | BH14: =AVERAGE(AV14,AX14,AZ14,BB14)*5 -> 2.7720872 | BI14: 4.7 | BJ14: 4.7 | BK14: 4.5 | BL14: 4.8 | BM14: 3.6 | BN14: =AVERAGE(Table1[[#This Row],[Tarea:Impresión 3D (Semana 13) (Real)]:[Tarea:Evaluación Final Sincrónica (Semana 17) (Real)]])*0.7+Table1[[#This Row],[nota asistencia]]*0.3 -> 3.9536262 | BO14: =AVERAGE(AA14,AQ14,BN14) -> 3.6162294
A15: 13 | B15: GUERRA CALVACHI | C15: SANTIAGO | D15: 1004217163 | E15: santiago.guerra@uao.edu.co | F15: 0.041458333 | G15: =IF(F15/$G$2<=1.001,F15/$G$2,0.6) -> 0.6 | H15: 0.039814815 | I15: =IF(H15/$I$2<=1.001,H15/$I$2,0.6) -> 1.0008729 | J15: 0.035960648 | K15: =IF(J15/$K$2<=1.001,J15/$K$2,0.6) -> 1.000322 | L15: 0.020798611 | M15: =IF(L15/$M$2<=1.001,L15/$M$2,0.6) -> 0.91496945 | N15: 0.042013889 | O15: =IF(N15/$O$2<=1.001,N15/$O$2,0.6) -> 0.90052096 | P15: 0.038773148 | Q15: =IF(P15/$Q$2<=1.001,P15/$Q$2,0.6) -> 0.89740155 | R15: =AVERAGE(G15,I15,K15,M15,Table1[[#This Row],[%Conexión5]],Table1[[#This Row],[%Conexión6]])*5 -> 4.4284056 | S15: 4 | T15: {=_xlfn.IFS(Table1[[#This Row],[Grupo]]=1,Sheet2!$B$1,Table1[[#This Row],[Grupo]]=2,Sheet2!$B$2,Table1[[#This Row],[Grupo]]=3,Sheet2!$B$3,Table1[[#This Row],[Grupo]]=4,Sheet2!$B$4,Table1[[#This Row],[Grupo]]=5,Sheet2!$B$5,Table1[[#This Row],[Grupo]]=6,Sheet2!$B$6,Table1[[#This Row],[Grupo]]=7,Sheet2!$B$7,Table1[[#This Row],[Grupo]]="","--")} -> Gesto correspondiente a la palabra "Durazno" en el lenguaje de señas colombiano | U15: 5 | V15: 5 | W15: 5 | X15: 5 | Y15: 4.3 | Z15: 4.5 | AA15: =AVERAGE(Table1[[#This Row],[Operaciones sobre piezas (Semana 2) ]:[Escaneo de partes anatómicas (Semana 6) ]])*0.7+Table1[[#This Row],[Asistencia]]*0.3 -> 4.6605217 | AB15: 0.041076389 | AC15: =IF(AB15/$AC$2<=1.01,AB15/$AC$2,0.6) -> 0.9980315 | AD15: 0.03599537 | AE15: =IF(AD15/$AE$2<=1.01,AD15/$AE$2,0.6) -> 0.95898859 | AF15: 0.027118056 | AG15: =IF(AF15/$AG$2<=1.01,AF15/$AG$2,0.6) -> 0.72247919 | AH15: 0.014722222 | AI15: =IF(AH15/$AI$2<=1.01,AH15/$AI$2,0.6) -> 1 | AJ15: 0.034756944 | AK15: =IF(AJ15/$AK$2<=1.01,AJ15/$AK$2,0.6) -> 0.96746134 | AL15: 0.010393519 | AM15: =IF(AL15/$AM$2<=1.01,AL15/$AM$2,0.6) -> 0.34658433 | AN15: =AVERAGE(AC15,AE15,AG15,AI15,AK15,AM15)*5 -> 4.1612875 | AO15: 5 | AP15: 3.6 | AQ15: =Table1[[#This Row],[Asistencia 2o Corte]]*0.3+AVERAGE(Table1[[#This Row],[Tarea:Introducción a 3DSlicer (Semana 8) (Real)]:[Tarea:Segmentación Manual y Semi-Automática (Semana 10) (Real)]])*0.7 -> 4.2583862 | AU15: 0.03712963 | AV15: =IF(AU15/$AV$2<=1.01,AU15/$AV$2,0.6) -> 1 | AW15: 0.032650463 | AX15: =IF(AW15/$AX$2<=1.01,AW15/$AX$2,0.6) -> 1 | AY15: 0.03625 | AZ15: =IF(AY15/$AZ$2<=1.01,AY15/$AZ$2,0.6) -> 0.99713467 | BA15: 0 | BB15: =IF(BA15/$BB$2<=1.01,BA15/$BB$2,0.6) -> 0 | BF15: https://oicampo-uao.github.io/academics/CABD/stl_final/Mandibula-2.stl | BH15: =AVERAGE(AV15,AX15,AZ15,BB15)*5 -> 3.7464183 | BI15: 5 | BJ15: 4.4 | BK15: 4.8 | BL15: 4.8 | BM15: 1.8 | BN15: =AVERAGE(Table1[[#This Row],[Tarea:Impresión 3D (Semana 13) (Real)]:[Tarea:Evaluación Final Sincrónica (Semana 17) (Real)]])*0.7+Table1[[#This Row],[nota asistencia]]*0.3 -> 4.0359255 | BO15: =AVERAGE(AA15,AQ15,BN15) -> 4.3182778
A16: 14 | B16: GUERRERO GIL | C16: JUAN MANUEL | D16: 1105366146 | E16: juan_m.guerrero@uao.edu.co | F16: 0.0384375 | G16: =IF(F16/$G$2<=1.001,F16/$G$2,0.6) -> 0.6 | H16: 0 | I16: =IF(H16/$I$2<=1.001,H16/$I$2,0.6) -> 0 | J16: 0.013148148 | K16: =IF(J16/$K$2<=1.001,J16/$K$2,0.6) -> 0.36574372 | L16: 0.007662037 | M16: =IF(L16/$M$2<=1.001,L16/$M$2,0.6) -> 0.33706721 | N16: 0.046215278 | O16: =IF(N16/$O$2<=1.001,N16/$O$2,0.6) -> 0.99057306 | P16: 0.043206019 | Q16: =IF(P16/$Q$2<=1.001,P16/$Q$2,0.6) -> 1 | R16: =AVERAGE(G16,I16,K16,M16,Table1[[#This Row],[%Conexión5]],Table1[[#This Row],[%Conexión6]])*5 -> 2.7444867 | S16: 5 | T16: {=_xlfn.IFS(Table1[[#This Row],[Grupo]]=1,Sheet2!$B$1,Table1[[#This Row],[Grupo]]=2,Sheet2!$B$2,Table1[[#This Row],[Grupo]]=3,Sheet2!$B$3,Table1[[#This Row],[Grupo]]=4,Sheet2!$B$4,Table1[[#This Row],[Grupo]]=5,Sheet2!$B$5,Table1[[#This Row],[Grupo]]=6,Sheet2!$B$6,Table1[[#This Row],[Grupo]]=7,Sheet2!$B$7,Table1[[#This Row],[Grupo]]="","--")} -> Gesto correspondiente a la palabra "Caracol" en el lenguaje de señas colombiano | U16: 4.5 | V16: 4 | W16: 5 | X16: 3.3 | Y16: 5 | Z16: 4.5 | AA16: =AVERAGE(Table1[[#This Row],[Operaciones sobre piezas (Semana 2) ]:[Escaneo de partes anatómicas (Semana 6) ]])*0.7+Table1[[#This Row],[Asistencia]]*0.3 -> 3.875346 | AB16: 0.033819444 | AC16: =IF(AB16/$AC$2<=1.01,AB16/$AC$2,0.6) -> 0.82170979 | AD16: 0.037384259 | AE16: =IF(AD16/$AE$2<=1.01,AD16/$AE$2,0.6) -> 0.99599137 | AF16: 0.038368056 | AG16: =IF(AF16/$AG$2<=1.01,AF16/$AG$2,0.6) -> 0.6 | AH16: 0.014722222 | AI16: =IF(AH16/$AI$2<=1.01,AH16/$AI$2,0.6) -> 1 | AJ16: 0.0094791667 | AK16: =IF(AJ16/$AK$2<=1.01,AJ16/$AK$2,0.6) -> 0.26385309 | AL16: 0.011168981 | AM16: =IF(AL16/$AM$2<=1.01,AL16/$AM$2,0.6) -> 0.37244307 | AN16: =AVERAGE(AC16,AE16,AG16,AI16,AK16,AM16)*5 -> 3.3783311 | AO16: 5 | AP16: 3.2 | AQ16: =Table1[[#This Row],[Asistencia 2o Corte]]*0.3+AVERAGE(Table1[[#This Row],[Tarea:Introducción a 3DSlicer (Semana 8) (Real)]:[Tarea:Segmentación Manual y Semi-Automática (Semana 10) (Real)]])*0.7 -> 3.8834993 | AT16: https://www.kaggle.com/code/madhuri42/sdp-liver-segmentation | AU16: 0.037048611 | AV16: =IF(AU16/$AV$2<=1.01,AU16/$AV$2,0.6) -> 0.99781796 | AW16: 0 | AX16: =IF(AW16/$AX$2<=1.01,AW16/$AX$2,0.6) -> 0 | AY16: 0.034907407 | AZ16: =IF(AY16/$AZ$2<=1.01,AY16/$AZ$2,0.6) -> 0.96020376 | BA16: 0.031944444 | BB16: =IF(BA16/$BB$2<=1.01,BA16/$BB$2,0.6) -> 0.93781855 | BF16: https://oicampo-uao.github.io/academics/CABD/stl_final/Mandibula-2.stl | BH16: =AVERAGE(AV16,AX16,AZ16,BB16)*5 -> 3.6198003 | BI16: 4.4 | BJ16: 3.5 | BK16: 4.3 | BL16: 3.8 | BM16: 3.2 | BN16: =AVERAGE(Table1[[#This Row],[Tarea:Impresión 3D (Semana 13) (Real)]:[Tarea:Evaluación Final Sincrónica (Semana 17) (Real)]])*0.7+Table1[[#This Row],[nota asistencia]]*0.3 -> 3.7739401 | BO16: =AVERAGE(AA16,AQ16,BN16) -> 3.8442618
A17: 15 | B17: GUZMAN CASTIBLANCO | C17: ESTEFANIA | D17: 1000940688 | E17: estefania.guzman@uao.edu.co | F17: 0.017361111 | G17: =IF(F17/$G$2<=1.001,F17/$G$2,0.6) -> 0.99535501 | H17: 0.039259259 | I17: =IF(H17/$I$2<=1.001,H17/$I$2,0.6) -> 0.98690719 | J17: 0.035949074 | K17: =IF(J17/$K$2<=1.001,J17/$K$2,0.6) -> 1 | L17: 0.022638889 | M17: =IF(L17/$M$2<=1.001,L17/$M$2,0.6) -> 0.99592668 | N17: 0.044965278 | O17: =IF(N17/$O$2<=1.001,N17/$O$2,0.6) -> 0.9637807 | P17: 0.041863426 | Q17: =IF(P17/$Q$2<=1.001,P17/$Q$2,0.6) -> 0.9689258 | R17: =AVERAGE(G17,I17,K17,M17,Table1[[#This Row],[%Conexión5]],Table1[[#This Row],[%Conexión6]])*5 -> 4.9257461 | S17: 2 | T17: {=_xlfn.IFS(Table1[[#This Row],[Grupo]]=1,Sheet2!$B$1,Table1[[#This Row],[Grupo]]=2,Sheet2!$B$2,Table1[[#This Row],[Grupo]]=3,Sheet2!$B$3,Table1[[#This Row],[Grupo]]=4,Sheet2!$B$4,Table1[[#This Row],[Grupo]]=5,Sheet2!$B$5,Table1[[#This Row],[Grupo]]=6,Sheet2!$B$6,Table1[[#This Row],[Grupo]]=7,Sheet2!$B$7,Table1[[#This Row],[Grupo]]="","--")} -> Gesto correspondiente a la palabra "Ratón" en el lenguaje de señas colombiano | U17: 5 | V17: 4.9 | W17: 5 | X17: 5 | Y17: 4.3 | Z17: 4.5 | AA17: =AVERAGE(Table1[[#This Row],[Operaciones sobre piezas (Semana 2) ]:[Escaneo de partes anatómicas (Semana 6) ]])*0.7+Table1[[#This Row],[Asistencia]]*0.3 -> 4.7957238 | AB17: 0.03818287 | AC17: =IF(AB17/$AC$2<=1.01,AB17/$AC$2,0.6) -> 0.92772778 | AD17: 0.037303241 | AE17: =IF(AD17/$AE$2<=1.01,AD17/$AE$2,0.6) -> 0.99383287 | AF17: 0.032152778 | AG17: =IF(AF17/$AG$2<=1.01,AF17/$AG$2,0.6) -> 0.85661425 | AH17: 0.014722222 | AI17: =IF(AH17/$AI$2<=1.01,AH17/$AI$2,0.6) -> 1 | AJ17: 0.035821759 | AK17: =IF(AJ17/$AK$2<=1.01,AJ17/$AK$2,0.6) -> 0.99710052 | AL17: 0.010462963 | AM17: =IF(AL17/$AM$2<=1.01,AL17/$AM$2,0.6) -> 0.34890004 | AN17: =AVERAGE(AC17,AE17,AG17,AI17,AK17,AM17)*5 -> 4.2701462 | AO17: 5 | AP17: 4.5 | AQ17: =Table1[[#This Row],[Asistencia 2o Corte]]*0.3+AVERAGE(Table1[[#This Row],[Tarea:Introducción a 3DSlicer (Semana 8) (Real)]:[Tarea:Segmentación Manual y Semi-Automática (Semana 10) (Real)]])*0.7 -> 4.6060439 | AT17: https://www.kaggle.com/datasets/kmader/finding-lungs-in-ct-data/data | AU17: 0.032719907 | AV17: =IF(AU17/$AV$2<=1.01,AU17/$AV$2,0.6) -> 0.88123441 | AW17: 0.032650463 | AX17: =IF(AW17/$AX$2<=1.01,AW17/$AX$2,0.6) -> 1 | AY17: 0.035069444 | AZ17: =IF(AY17/$AZ$2<=1.01,AY17/$AZ$2,0.6) -> 0.96466094 | BA17: 0.033402778 | BB17: =IF(BA17/$BB$2<=1.01,BA17/$BB$2,0.6) -> 0.98063201 | BD17: https://drive.google.com/file/d/1UKYI8aEgFPXYCVomvusbK0FEXj_C21qt/view?usp=sharing | BF17: https://oicampo-uao.github.io/academics/CABD/stl_final/Mandibula-2.stl | BH17: =AVERAGE(AV17,AX17,AZ17,BB17)*5 -> 4.7831592 | BI17: 4.7 | BJ17: 4.7 | BK17: 4.5 | BL17: 4.8 | BM17: 3.6 | BN17: =AVERAGE(Table1[[#This Row],[Tarea:Impresión 3D (Semana 13) (Real)]:[Tarea:Evaluación Final Sincrónica (Semana 17) (Real)]])*0.7+Table1[[#This Row],[nota asistencia]]*0.3 -> 4.5569478 | BO17: =AVERAGE(AA17,AQ17,BN17) -> 4.6529052
A18: 16 | B18: JIMENEZ CARDONA | C18: ANA MARIA | D18: 1112388246 | E18: ana.jimenez_cardona@uao.edu.co | F18: 0.01744213 | G18: =IF(F18/$G$2<=1.001,F18/$G$2,0.6) -> 1 | H18: 0.038506944 | I18: =IF(H18/$I$2<=1.001,H18/$I$2,0.6) -> 0.96799534 | J18: 0.010486111 | K18: =IF(J18/$K$2<=1.001,J18/$K$2,0.6) -> 0.2916935 | L18: 0.022592593 | M18: =IF(L18/$M$2<=1.001,L18/$M$2,0.6) -> 0.99389002 | N18: 0.037476852 | O18: =IF(N18/$O$2<=1.001,N18/$O$2,0.6) -> 0.80327462 | P18: 0.038391204 | Q18: =IF(P18/$Q$2<=1.001,P18/$Q$2,0.6) -> 0.88856148 | R18: =AVERAGE(G18,I18,K18,M18,Table1[[#This Row],[%Conexión5]],Table1[[#This Row],[%Conexión6]])*5 -> 4.1211791 | S18: 2 | T18: {=_xlfn.IFS(Table1[[#This Row],[Grupo]]=1,Sheet2!$B$1,Table1[[#This Row],[Grupo]]=2,Sheet2!$B$2,Table1[[#This Row],[Grupo]]=3,Sheet2!$B$3,Table1[[#This Row],[Grupo]]=4,Sheet2!$B$4,Table1[[#This Row],[Grupo]]=5,Sheet2!$B$5,Table1[[#This Row],[Grupo]]=6,Sheet2!$B$6,Table1[[#This Row],[Grupo]]=7,Sheet2!$B$7,Table1[[#This Row],[Grupo]]="","--")} -> Gesto correspondiente a la palabra "Ratón" en el lenguaje de señas colombiano | U18: 4.8 | V18: 3.3 | W18: 5 | X18: 5 | Y18: 5 | Z18: 4.5 | AA18: =AVERAGE(Table1[[#This Row],[Operaciones sobre piezas (Semana 2) ]:[Escaneo de partes anatómicas (Semana 6) ]])*0.7+Table1[[#This Row],[Asistencia]]*0.3 -> 4.4283537 | AB18: 0.032685185 | AC18: =IF(AB18/$AC$2<=1.01,AB18/$AC$2,0.6) -> 0.79415073 | AD18: 0.02212963 | AE18: =IF(AD18/$AE$2<=1.01,AD18/$AE$2,0.6) -> 0.58957755 | AF18: 0.018831019 | AG18: =IF(AF18/$AG$2<=1.01,AF18/$AG$2,0.6) -> 0.50169596 | AH18: 0.014722222 | AI18: =IF(AH18/$AI$2<=1.01,AH18/$AI$2,0.6) -> 1 | AJ18: 0.033402778 | AK18: =IF(AJ18/$AK$2<=1.01,AJ18/$AK$2,0.6) -> 0.92976804 | AL18: 0.01380787 | AM18: =IF(AL18/$AM$2<=1.01,AL18/$AM$2,0.6) -> 0.46043998 | AN18: =AVERAGE(AC18,AE18,AG18,AI18,AK18,AM18)*5 -> 3.5630269 | AO18: 4.2 | AP18: 3.6 | AQ18: =Table1[[#This Row],[Asistencia 2o Corte]]*0.3+AVERAGE(Table1[[#This Row],[Tarea:Introducción a 3DSlicer (Semana 8) (Real)]:[Tarea:Segmentación Manual y Semi-Automática (Semana 10) (Real)]])*0.7 -> 3.7989081 | AS18: CT Abdomen: Segmentación automática y comparar con segmentación manual de 3 órganos | AT18: Pulmones (usen las imágenes 3D) | AU18: 0.022650463 | AV18: =IF(AU18/$AV$2<=1.01,AU18/$AV$2,0.6) -> 0.61003741 | AW18: 0.031238426 | AX18: =IF(AW18/$AX$2<=1.01,AW18/$AX$2,0.6) -> 0.95675292 | AY18: 0.0020833333 | AZ18: =IF(AY18/$AZ$2<=1.01,AY18/$AZ$2,0.6) -> 0.05730659 | BA18: 0.028564815 | BB18: =IF(BA18/$BB$2<=1.01,BA18/$BB$2,0.6) -> 0.83860007 | BC18: CT-Liver Fémur der. | BD18: Mandibula (lado izq) | BE18: https://drive.google.com/file/d/1OkRZCmaB2vymPkWxXspya_hDijiDJe9z/view?usp=sharing | BF18: https://oicampo-uao.github.io/academics/CABD/stl_final/Femur-2.mix | BH18: =AVERAGE(AV18,AX18,AZ18,BB18)*5 -> 3.0783712 | BI18: 4.7 | BJ18: 4.7 | BK18: 4.5 | BL18: 4.8 | BM18: 0 | BN18: =AVERAGE(Table1[[#This Row],[Tarea:Impresión 3D (Semana 13) (Real)]:[Tarea:Evaluación Final Sincrónica (Semana 17) (Real)]])*0.7+Table1[[#This Row],[nota asistencia]]*0.3 -> 3.5415114 | BO18: =AVERAGE(AA18,AQ18,BN18) -> 3.9229244
A19: 17 | B19: LONDOÑO LOPEZ | C19: ALLISON | D19: 1110286885 | E19: allison.londono@uao.edu.co | F19: 0.017349537 | G19: =IF(F19/$G$2<=1.001,F19/$G$2,0.6) -> 0.99469144 | H19: 0.039293981 | I19: =IF(H19/$I$2<=1.001,H19/$I$2,0.6) -> 0.98778004 | J19: 0.035925926 | K19: =IF(J19/$K$2<=1.001,J19/$K$2,0.6) -> 0.99935608 | L19: 0.02212963 | M19: =IF(L19/$M$2<=1.001,L19/$M$2,0.6) -> 0.97352342 | N19: 0.045590278 | O19: =IF(N19/$O$2<=1.001,N19/$O$2,0.6) -> 0.97717688 | P19: 0.043206019 | Q19: =IF(P19/$Q$2<=1.001,P19/$Q$2,0.6) -> 1 | R19: =AVERAGE(G19,I19,K19,M19,Table1[[#This Row],[%Conexión5]],Table1[[#This Row],[%Conexión6]])*5 -> 4.9437732 | S19: 1 | T19: {=_xlfn.IFS(Table1[[#This Row],[Grupo]]=1,Sheet2!$B$1,Table1[[#This Row],[Grupo]]=2,Sheet2!$B$2,Table1[[#This Row],[Grupo]]=3,Sheet2!$B$3,Table1[[#This Row],[Grupo]]=4,Sheet2!$B$4,Table1[[#This Row],[Grupo]]=5,Sheet2!$B$5,Table1[[#This Row],[Grupo]]=6,Sheet2!$B$6,Table1[[#This Row],[Grupo]]=7,Sheet2!$B$7,Table1[[#This Row],[Grupo]]="","--")} -> Gesto correspondiente a la palabra "Tortuga" en el lenguaje de señas colombiano | U19: 4 | V19: 0 | W19: 2.1 | X19: 1.1 | Y19: 0 | Z19: 1.7 | AA19: =AVERAGE(Table1[[#This Row],[Operaciones sobre piezas (Semana 2) ]:[Escaneo de partes anatómicas (Semana 6) ]])*0.7+Table1[[#This Row],[Asistencia]]*0.3 -> 2.169132 | AB19: 0.041203704 | AC19: =IF(AB19/$AC$2<=1.01,AB19/$AC$2,0.6) -> 1.0011249 | AD19: 0.037314815 | AE19: =IF(AD19/$AE$2<=1.01,AD19/$AE$2,0.6) -> 0.99414123 | AF19: 0.038368056 | AG19: 1 | AH19: 0.014722222 | AI19: =IF(AH19/$AI$2<=1.01,AH19/$AI$2,0.6) -> 1 | AJ19: 0.026469907 | AK19: =IF(AJ19/$AK$2<=1.01,AJ19/$AK$2,0.6) -> 0.73679124 | AL19: 0.012256944 | AM19: =IF(AL19/$AM$2<=1.01,AL19/$AM$2,0.6) -> 0.4087225 | AN19: =AVERAGE(AC19,AE19,AG19,AI19,AK19,AM19)*5 -> 4.2839832 | AO19: 5 | AP19: 2.5 | AQ19: =Table1[[#This Row],[Asistencia 2o Corte]]*0.3+AVERAGE(Table1[[#This Row],[Tarea:Introducción a 3DSlicer (Semana 8) (Real)]:[Tarea:Segmentación Manual y Semi-Automática (Semana 10) (Real)]])*0.7 -> 3.910195 | AS19: CT Liver: Segmentación automática y comparar con segmentación manual de 3 órganos | AT19: Corazón | AU19: 0.032835648 | AV19: =IF(AU19/$AV$2<=1.01,AU19/$AV$2,0.6) -> 0.88435162 | AW19: 0.032650463 | AX19: =IF(AW19/$AX$2<=1.01,AW19/$AX$2,0.6) -> 1 | AY19: 0.036481481 | AZ19: =IF(AY19/$AZ$2<=1.01,AY19/$AZ$2,0.6) -> 1.0035021 | BA19: 0.031365741 | BB19: =IF(BA19/$BB$2<=1.01,BA19/$BB$2,0.6) -> 0.92082909 | BC19: CT-Liver Fémur izq. | BD19: Mandibula (lado der) | BE19: https://drive.google.com/file/d/1D5vRi6mOSqsDbb885Oqgb8bB75Q5HPRr/view?usp=sharing | BF19: https://oicampo-uao.github.io/academics/CABD/stl_final/Femur-1.mix | BG19: https://oicampo-uao.github.io/academics/CABD/stl_final/Mandibula-1.stl | BH19: =AVERAGE(AV19,AX19,AZ19,BB19)*5 -> 4.7608535 | BI19: 4.4 | BJ19: 3.8 | BK19: 1.9 | BL19: 0 | BM19: 0 | BN19: =AVERAGE(Table1[[#This Row],[Tarea:Impresión 3D (Semana 13) (Real)]:[Tarea:Evaluación Final Sincrónica (Semana 17) (Real)]])*0.7+Table1[[#This Row],[nota asistencia]]*0.3 -> 2.842256 | BO19: =AVERAGE(AA19,AQ19,BN19) -> 2.973861
A20: 18 | B20: MONCADA CASALLAS | C20: SANTIAGO | D20: 1094883894 | E20: santiago.moncada@uao.edu.co | F20: 0 | G20: =IF(F20/$G$2<=1.001,F20/$G$2,0.6) -> 0 | H20: 0.037743056 | I20: =IF(H20/$I$2<=1.001,H20/$I$2,0.6) -> 0.94879255 | J20: 0.028715278 | K20: =IF(J20/$K$2<=1.001,J20/$K$2,0.6) -> 0.79877656 | L20: 0.019212963 | M20: =IF(L20/$M$2<=1.001,L20/$M$2,0.6) -> 0.84521385 | N20: 0 | O20: =IF(N20/$O$2<=1.001,N20/$O$2,0.6) -> 0 | P20: 0 | Q20: =IF(P20/$Q$2<=1.001,P20/$Q$2,0.6) -> 0 | R20: =AVERAGE(G20,I20,K20,M20,Table1[[#This Row],[%Conexión5]],Table1[[#This Row],[%Conexión6]])*5 -> 2.1606525 | T20: {=_xlfn.IFS(Table1[[#This Row],[Grupo]]=1,Sheet2!$B$1,Table1[[#This Row],[Grupo]]=2,Sheet2!$B$2,Table1[[#This Row],[Grupo]]=3,Sheet2!$B$3,Table1[[#This Row],[Grupo]]=4,Sheet2!$B$4,Table1[[#This Row],[Grupo]]=5,Sheet2!$B$5,Table1[[#This Row],[Grupo]]=6,Sheet2!$B$6,Table1[[#This Row],[Grupo]]=7,Sheet2!$B$7,Table1[[#This Row],[Grupo]]="","--")} -> -- | U20: 0 | V20: 0 | W20: 0 | X20: 0 | Y20: 0 | Z20: 0 | AA20: =AVERAGE(Table1[[#This Row],[Operaciones sobre piezas (Semana 2) ]:[Escaneo de partes anatómicas (Semana 6) ]])*0.7+Table1[[#This Row],[Asistencia]]*0.3 -> 0.64819574 | AB20: 0 | AC20: =IF(AB20/$AC$2<=1.01,AB20/$AC$2,0.6) -> 0 | AD20: 0.037384259 | AE20: =IF(AD20/$AE$2<=1.01,AD20/$AE$2,0.6) -> 0.99599137 | AF20: 0 | AG20: =IF(AF20/$AG$2<=1.01,AF20/$AG$2,0.6) -> 0 | AH20: 0 | AI20: =IF(AH20/$AI$2<=1.01,AH20/$AI$2,0.6) -> 0 | AJ20: 0 | AK20: =IF(AJ20/$AK$2<=1.01,AJ20/$AK$2,0.6) -> 0 | AL20: 0.0055671296 | AM20: =IF(AL20/$AM$2<=1.01,AL20/$AM$2,0.6) -> 0.18564261 | AN20: =AVERAGE(AC20,AE20,AG20,AI20,AK20,AM20)*5 -> 0.98469498 | AO20: 0 | AP20: 0 | AQ20: =Table1[[#This Row],[Asistencia 2o Corte]]*0.3+AVERAGE(Table1[[#This Row],[Tarea:Introducción a 3DSlicer (Semana 8) (Real)]:[Tarea:Segmentación Manual y Semi-Automática (Semana 10) (Real)]])*0.7 -> 0.29540849 | AU20: 0 | AV20: =IF(AU20/$AV$2<=1.01,AU20/$AV$2,0.6) -> 0 | AW20: 0 | AX20: =IF(AW20/$AX$2<=1.01,AW20/$AX$2,0.6) -> 0 | AY20: 0 | AZ20: =IF(AY20/$AZ$2<=1.01,AY20/$AZ$2,0.6) -> 0 | BA20: 0 | BB20: =IF(BA20/$BB$2<=1.01,BA20/$BB$2,0.6) -> 0 | BH20: =AVERAGE(AV20,AX20,AZ20,BB20)*5 -> 0 | BI20: 0 | BJ20: 0 | BK20: 0 | BL20: 0 | BM20: 0 | BN20: =AVERAGE(Table1[[#This Row],[Tarea:Impresión 3D (Semana 13) (Real)]:[Tarea:Evaluación Final Sincrónica (Semana 17) (Real)]])*0.7+Table1[[#This Row],[nota asistencia]]*0.3 -> 0 | BO20: =AVERAGE(AA20,AQ20,BN20) -> 0.31453474
A21: 19 | B21: MONZON SANDOVAL | C21: ORIANA | D21: 1005832925 | E21: oriana.monznn@uao.edu.co | F21: 0.017314815 | G21: =IF(F21/$G$2<=1.001,F21/$G$2,0.6) -> 0.99270073 | H21: 0.039814815 | I21: =IF(H21/$I$2<=1.001,H21/$I$2,0.6) -> 1.0008729 | J21: 0.035868056 | K21: =IF(J21/$K$2<=1.001,J21/$K$2,0.6) -> 0.9977463 | L21: 0.021909722 | M21: =IF(L21/$M$2<=1.001,L21/$M$2,0.6) -> 0.96384929 | N21: 0.046631944 | O21: =IF(N21/$O$2<=1.001,N21/$O$2,0.6) -> 0.99950385 | P21: 0.042488426 | Q21: =IF(P21/$Q$2<=1.001,P21/$Q$2,0.6) -> 0.98339137 | R21: =AVERAGE(G21,I21,K21,M21,Table1[[#This Row],[%Conexión5]],Table1[[#This Row],[%Conexión6]])*5 -> 4.948387 | S21: 3 | T21: {=_xlfn.IFS(Table1[[#This Row],[Grupo]]=1,Sheet2!$B$1,Table1[[#This Row],[Grupo]]=2,Sheet2!$B$2,Table1[[#This Row],[Grupo]]=3,Sheet2!$B$3,Table1[[#This Row],[Grupo]]=4,Sheet2!$B$4,Table1[[#This Row],[Grupo]]=5,Sheet2!$B$5,Table1[[#This Row],[Grupo]]=6,Sheet2!$B$6,Table1[[#This Row],[Grupo]]=7,Sheet2!$B$7,Table1[[#This Row],[Grupo]]="","--")} -> Gesto correspondiente a la palabra "Oveja" en el lenguaje de señas colombiano | U21: 5 | V21: 5 | W21: 5 | X21: 5 | Y21: 5 | Z21: 4.5 | AA21: =AVERAGE(Table1[[#This Row],[Operaciones sobre piezas (Semana 2) ]:[Escaneo de partes anatómicas (Semana 6) ]])*0.7+Table1[[#This Row],[Asistencia]]*0.3 -> 4.9145161 | AB21: 0.03837963 | AC21: =IF(AB21/$AC$2<=1.01,AB21/$AC$2,0.6) -> 0.93250844 | AD21: 0.033958333 | AE21: =IF(AD21/$AE$2<=1.01,AD21/$AE$2,0.6) -> 0.90471785 | AF21: 0.038368056 | AG21: 1 | AH21: 0.014722222 | AI21: =IF(AH21/$AI$2<=1.01,AH21/$AI$2,0.6) -> 1 | AJ21: 0.035925926 | AK21: =IF(AJ21/$AK$2<=1.01,AJ21/$AK$2,0.6) -> 1 | AL21: 0.012233796 | AM21: =IF(AL21/$AM$2<=1.01,AL21/$AM$2,0.6) -> 0.4079506 | AN21: =AVERAGE(AC21,AE21,AG21,AI21,AK21,AM21)*5 -> 4.3709807 | AO21: 5 | AP21: 4.3 | AQ21: =Table1[[#This Row],[Asistencia 2o Corte]]*0.3+AVERAGE(Table1[[#This Row],[Tarea:Introducción a 3DSlicer (Semana 8) (Real)]:[Tarea:Segmentación Manual y Semi-Automática (Semana 10) (Real)]])*0.7 -> 4.5662942 | AT21: https://www.kaggle.com/datasets/darksteeldragon/brats2020-nifti-format-for-deepmedic | AU21: 0.035590278 | AV21: =IF(AU21/$AV$2<=1.01,AU21/$AV$2,0.6) -> 0.95854115 | AW21: 0.032083333 | AX21: =IF(AW21/$AX$2<=1.01,AW21/$AX$2,0.6) -> 0.98263027 | AY21: 0.035949074 | AZ21: =IF(AY21/$AZ$2<=1.01,AY21/$AZ$2,0.6) -> 0.98885705 | BA21: 0.031516204 | BB21: =IF(BA21/$BB$2<=1.01,BA21/$BB$2,0.6) -> 0.92524635 | BD21: Mandíbula (lado der) | BF21: https://oicampo-uao.github.io/academics/CABD/stl_final/Mandibula-2.stl | BH21: =AVERAGE(AV21,AX21,AZ21,BB21)*5 -> 4.8190935 | BI21: 5 | BJ21: 4.7 | BK21: 4.8 | BL21: 4.3 | BM21: 3.8 | BN21: =AVERAGE(Table1[[#This Row],[Tarea:Impresión 3D (Semana 13) (Real)]:[Tarea:Evaluación Final Sincrónica (Semana 17) (Real)]])*0.7+Table1[[#This Row],[nota asistencia]]*0.3 -> 4.6097281 | BO21: =AVERAGE(AA21,AQ21,BN21) -> 4.6968461
A22: 20 | B22: MOSQUERA AMADOR | C22: VALERIA | D22: 1002886235 | E22: valeria.mosquera@uao.edu.co | F22: 0.017395833 | G22: =IF(F22/$G$2<=1.001,F22/$G$2,0.6) -> 0.99734572 | H22: 0.038217593 | I22: =IF(H22/$I$2<=1.001,H22/$I$2,0.6) -> 0.96072156 | J22: 0.035960648 | K22: =IF(J22/$K$2<=1.001,J22/$K$2,0.6) -> 1.000322 | L22: 0.022662037 | M22: =IF(L22/$M$2<=1.001,L22/$M$2,0.6) -> 0.99694501 | N22: 0.046666667 | O22: =IF(N22/$O$2<=1.001,N22/$O$2,0.6) -> 1.0002481 | P22: 0.043206019 | Q22: =IF(P22/$Q$2<=1.001,P22/$Q$2,0.6) -> 1 | R22: =AVERAGE(G22,I22,K22,M22,Table1[[#This Row],[%Conexión5]],Table1[[#This Row],[%Conexión6]])*5 -> 4.9629853 | S22: 7 | T22: {=_xlfn.IFS(Table1[[#This Row],[Grupo]]=1,Sheet2!$B$1,Table1[[#This Row],[Grupo]]=2,Sheet2!$B$2,Table1[[#This Row],[Grupo]]=3,Sheet2!$B$3,Table1[[#This Row],[Grupo]]=4,Sheet2!$B$4,Table1[[#This Row],[Grupo]]=5,Sheet2!$B$5,Table1[[#This Row],[Grupo]]=6,Sheet2!$B$6,Table1[[#This Row],[Grupo]]=7,Sheet2!$B$7,Table1[[#This Row],[Grupo]]="","--")} -> Gesto correspondiente a la palabra "Flor" en el lenguaje de señas colombiano | U22: 4.6 | V22: 4.5 | W22: 4.8 | X22: 3.3 | Y22: 4.8 | Z22: 4.5 | AA22: =AVERAGE(Table1[[#This Row],[Operaciones sobre piezas (Semana 2) ]:[Escaneo de partes anatómicas (Semana 6) ]])*0.7+Table1[[#This Row],[Asistencia]]*0.3 -> 4.5548956 | AB22: 0.041157407 | AC22: =IF(AB22/$AC$2<=1.01,AB22/$AC$2,0.6) -> 1 | AD22: 0 | AE22: =IF(AD22/$AE$2<=1.01,AD22/$AE$2,0.6) -> 0 | AF22: 0.038368056 | AG22: 1 | AH22: 0.014722222 | AI22: =IF(AH22/$AI$2<=1.01,AH22/$AI$2,0.6) -> 1 | AJ22: 0.035925926 | AK22: =IF(AJ22/$AK$2<=1.01,AJ22/$AK$2,0.6) -> 1 | AL22: 0.025740741 | AM22: =IF(AL22/$AM$2<=1.01,AL22/$AM$2,0.6) -> 0.85835585 | AN22: =AVERAGE(AC22,AE22,AG22,AI22,AK22,AM22)*5 -> 4.0486299 | AO22: 5 | AP22: 3.4 | AQ22: =Table1[[#This Row],[Asistencia 2o Corte]]*0.3+AVERAGE(Table1[[#This Row],[Tarea:Introducción a 3DSlicer (Semana 8) (Real)]:[Tarea:Segmentación Manual y Semi-Automática (Semana 10) (Real)]])*0.7 -> 4.154589 | AU22: 0.03712963 | AV22: =IF(AU22/$AV$2<=1.01,AU22/$AV$2,0.6) -> 1 | AW22: 0.032650463 | AX22: =IF(AW22/$AX$2<=1.01,AW22/$AX$2,0.6) -> 1 | AY22: 0.03630787 | AZ22: =IF(AY22/$AZ$2<=1.01,AY22/$AZ$2,0.6) -> 0.99872652 | BA22: 0.034074074 | BB22: =IF(BA22/$BB$2<=1.01,BA22/$BB$2,0.6) -> 1.0003398 | BF22: https://oicampo-uao.github.io/academics/CABD/stl_final/Mandibula-2.stl | BH22: =AVERAGE(AV22,AX22,AZ22,BB22)*5 -> 4.9988329 | BI22: 4.7 | BJ22: 4.1 | BK22: 4 | BL22: 4.5 | BM22: 0 | BN22: =AVERAGE(Table1[[#This Row],[Tarea:Impresión 3D (Semana 13) (Real)]:[Tarea:Evaluación Final Sincrónica (Semana 17) (Real)]])*0.7+Table1[[#This Row],[nota asistencia]]*0.3 -> 3.9216499 | BO22: =AVERAGE(AA22,AQ22,BN22) -> 4.2103781
A23: r | B23: MUÑOZ BECERRA | C23: ISABELLA | D23: 1112388822 | E23: isabella.munoz_bec@uao.edu.co | F23: 0.017337963 | G23: =IF(F23/$G$2<=1.001,F23/$G$2,0.6) -> 0.99402787 | H23: 0.039224537 | I23: =IF(H23/$I$2<=1.001,H23/$I$2,0.6) -> 0.98603433 | J23: 0.03587963 | K23: =IF(J23/$K$2<=1.001,J23/$K$2,0.6) -> 0.99806825 | L23: 0 | M23: =IF(L23/$M$2<=1.001,L23/$M$2,0.6) -> 0 | N23: 0.032685185 | O23: =IF(N23/$O$2<=1.001,N23/$O$2,0.6) -> 0.70057058 | P23: 0.033252315 | Q23: =IF(P23/$Q$2<=1.001,P23/$Q$2,0.6) -> 0.76962229 | R23: =AVERAGE(G23,I23,K23,M23,Table1[[#This Row],[%Conexión5]],Table1[[#This Row],[%Conexión6]])*5 -> 3.7069361 | S23: 4 | T23: {=_xlfn.IFS(Table1[[#This Row],[Grupo]]=1,Sheet2!$B$1,Table1[[#This Row],[Grupo]]=2,Sheet2!$B$2,Table1[[#This Row],[Grupo]]=3,Sheet2!$B$3,Table1[[#This Row],[Grupo]]=4,Sheet2!$B$4,Table1[[#This Row],[Grupo]]=5,Sheet2!$B$5,Table1[[#This Row],[Grupo]]=6,Sheet2!$B$6,Table1[[#This Row],[Grupo]]=7,Sheet2!$B$7,Table1[[#This Row],[Grupo]]="","--")} -> Gesto correspondiente a la palabra "Durazno" en el lenguaje de señas colombiano | U23: 4.5 | V23: 4.8 | W23: 4 | X23: 3.3 | Y23: 5 | Z23: 4.5 | AA23: =AVERAGE(Table1[[#This Row],[Operaciones sobre piezas (Semana 2) ]:[Escaneo de partes anatómicas (Semana 6) ]])*0.7+Table1[[#This Row],[Asistencia]]*0.3 -> 4.1360808 | AB23: 0.032615741 | AC23: =IF(AB23/$AC$2<=1.01,AB23/$AC$2,0.6) -> 0.79246344 | AD23: 0.029525463 | AE23: =IF(AD23/$AE$2<=1.01,AD23/$AE$2,0.6) -> 0.78661733 | AF23: 0.037488426 | AG23: =IF(AF23/$AG$2<=1.01,AF23/$AG$2,0.6) -> 0.99876657 | AH23: 0 | AI23: =IF(AH23/$AI$2<=1.01,AH23/$AI$2,0.6) -> 0 | AJ23: 0.0040162037 | AK23: =IF(AJ23/$AK$2<=1.01,AJ23/$AK$2,0.6) -> 0.11179124 | AL23: 0.017407407 | AM23: =IF(AL23/$AM$2<=1.01,AL23/$AM$2,0.6) -> 0.58047086 | AN23: =AVERAGE(AC23,AE23,AG23,AI23,AK23,AM23)*5 -> 2.7250912 | AO23: 5 | AP23: 3.6 | AQ23: =Table1[[#This Row],[Asistencia 2o Corte]]*0.3+AVERAGE(Table1[[#This Row],[Tarea:Introducción a 3DSlicer (Semana 8) (Real)]:[Tarea:Segmentación Manual y Semi-Automática (Semana 10) (Real)]])*0.7 -> 3.8275274 | AT23: https://www.kaggle.com/datasets/junyussh/tcga-kirp | AU23: 0.027766204 | AV23: =IF(AU23/$AV$2<=1.01,AU23/$AV$2,0.6) -> 0.74781796 | AW23: 0.030046296 | AX23: =IF(AW23/$AX$2<=1.01,AW23/$AX$2,0.6) -> 0.92024105 | AY23: 0.036481481 | AZ23: =IF(AY23/$AZ$2<=1.01,AY23/$AZ$2,0.6) -> 1.0035021 | BA23: 0.025104167 | BB23: =IF(BA23/$BB$2<=1.01,BA23/$BB$2,0.6) -> 0.73700306 | BD23: Mandíbula (lado der) | BF23: https://oicampo-uao.github.io/academics/CABD/stl_final/Pierna-1.mix | BH23: =AVERAGE(AV23,AX23,AZ23,BB23)*5 -> 4.2607052 | BI23: 5 | BJ23: 4.4 | BK23: 4.8 | BL23: 4.8 | BM23: 3.6 | BN23: =AVERAGE(Table1[[#This Row],[Tarea:Impresión 3D (Semana 13) (Real)]:[Tarea:Evaluación Final Sincrónica (Semana 17) (Real)]])*0.7+Table1[[#This Row],[nota asistencia]]*0.3 -> 4.4422115 | BO23: =AVERAGE(AA23,AQ23,BN23) -> 4.1352732
